<?xml version="1.0"?>
<robot xmlns:xacro="http://www.ros.org/wiki/xacro" name="whill" >

    <link name="base_link">
    </link>

    <link name="base_floor">
        <visual>
            <geometry>
                <box size="0.600 0.400 0.050"/>
            </geometry>
            <material name="grey">
                <color rgba="0.5 0.5 0.5 1.0"/>
            </material>
        </visual>

        <collision>
            <geometry>
                <box size="0.600 0.400 0.050"/>
            </geometry>
        </collision>

        <inertial>
            <origin xyz="0 0 0" rpy="0 0 0" />
            <mass value="40" />
            <inertia ixx="1.0"  ixy="0.0"   ixz="0.0"
                                iyy="1.0"   iyz="0.0"
                                            izz="1.0" />
        </inertial>
    </link>

    <joint name="base_body_joint" type="fixed">
        <parent link="base_link" />
        <child link="base_floor" />
        <origin xyz="0.3 0 0.0" rpy="0 0 0"/>
    </joint>

    <link name="footrest_link">
        <collision>
            <geometry>
                <box size="0.250 0.260 0.050"/>
            </geometry>
        </collision>
        <visual>
            <geometry>
                <box size="0.250 0.260 0.050"/>
            </geometry>
            <material name="grey">
                <color rgba="0.5 0.5 0.5 1.0"/>
            </material>
        </visual>
        <inertial>
            <origin xyz="0 0 0" rpy="0 0 0" />
            <mass value="1" />
            <inertia ixx="1.0"  ixy="0.0"   ixz="0.0"
                                iyy="1.0"   iyz="0.0"
                                            izz="1.0" />
        </inertial>
    </link>

    <joint name="footrest_joint" type="fixed">
        <parent link="base_floor" />
        <child link="footrest_link" />
        <origin xyz="0.320 0 0" rpy="0 0 0"/>
    </joint>

    <link name="left_wheel_link">
        <visual>
            <geometry>
                <cylinder length="0.05" radius="0.1325"/>
            </geometry>
            <origin xyz="0 0 0" rpy="0 0 0" />
            <material name="black" />
        </visual>

        <collision>
            <geometry>
                <cylinder length="0.05" radius="0.1325"/>
            </geometry>
        </collision> 

        <inertial>
            <origin xyz="0 0 0"/>
            <mass value="0.500"/>
            <inertia ixx="0.0013541667" ixy="0" ixz="0" iyy="0.0013541667" iyz="0" izz="0.0025"/>
        </inertial>
    </link>

    <joint name="leftWheel" type="continuous">
        <parent link="base_floor" />
        <child link="left_wheel_link" />
        <origin xyz="-0.3 0.245 0" rpy="1.57 0 0" />
        <axis xyz="0 0 -1" />
    </joint>

    <link name="right_wheel_link">
        <collision>
            <origin xyz="0 0 0" rpy="0 0 0" />
            <geometry>
                <cylinder length="0.05" radius="0.1325"/>
            </geometry>
        </collision>
        <visual>
            <origin xyz="0 0 0" rpy="0 0 0" />
            <geometry>
                <cylinder length="0.05" radius="0.1325"/>
            </geometry>
            <material name="black" />
        </visual>
        <inertial>
            <origin xyz="0 0 0"/>
            <mass value="0.500"/>
            <inertia ixx="0.0013541667" ixy="0" ixz="0" iyy="0.0013541667" iyz="0" izz="0.0025"/>
        </inertial>
    </link>

    <joint name="rightWheel" type="continuous">
        <parent link="base_floor" />
        <child link="right_wheel_link" />
        <origin xyz="-0.3 -0.245 0" rpy="-1.57 0 0" />
        <axis xyz="0 0 1" />
    </joint>

    <link name="frontwheel_left">
        <collision>
            <geometry>
                <cylinder length="0.05" radius="0.1325"/>
            </geometry>
        </collision>

        <visual>
            <geometry>
                <cylinder length="0.05" radius="0.1325"/>
            </geometry>
            <material name="black" />
        </visual>

        <inertial>
            <origin xyz="0 0 0" rpy="0 0 0" />
            <mass value="1.0" />
            <inertia ixx="1.0"  ixy="0.0"   ixz="0.0"
                                iyy="1.0"   iyz="0.0"
                                            izz="1.0" />
        </inertial>
    </link>
    
    <joint name="frontwheel_left_joint" type="fixed">
        <parent link="base_floor" />
        <child link="frontwheel_left" />
        <origin xyz="0.3 -0.245 0" rpy="1.57 0 0" />
        <axis xyz="0 0 -1" />
    </joint>

    <link name="frontwheel_right">
        <collision>
            <geometry>
                <cylinder length="0.05" radius="0.1325"/>
            </geometry>
        </collision>

        <visual>
            <geometry>
                <cylinder length="0.05" radius="0.1325"/>
            </geometry>
            <material name="black" />
        </visual>

        <inertial>
            <origin xyz="0 0 0" rpy="0 0 0" />
            <mass value="1.0" />
            <inertia ixx="1.0"  ixy="0.0"   ixz="0.0"
                                iyy="1.0"   iyz="0.0"
                                            izz="1.0" />
        </inertial>    
    </link>

    <joint name="frontwheel_right_joint" type="fixed">
        <parent link="base_floor" />
        <child link="frontwheel_right"/>
        <origin xyz="0.3 0.245 0" rpy="1.57 0 0" />
        <axis xyz="0 0 1" />
    </joint>

     <!-- ===============  IMU =============== -->
    <link name="imu">
    <visual>
        <origin xyz="0 0 0" rpy="0 0 0" />
            <geometry>
                <box size="0.02 0.02 0.02"/>
            </geometry>
            <material name="Blue" />
        </visual>
    </link>

    <joint name="imu_joint" type="fixed">
        <parent link="base_floor"/>
        <child link="imu"/>
        <axis xyz="0 1 0" />
        <origin xyz="0.02 0 0.05" rpy="0 0.85521133347 3.14159265359"/>
    </joint>

    <!-- =============== Sensor =============== -->
    <!-- =============== Camera =============== -->
    <link name="camera_link">
    <visual>
      <origin xyz="0 0 0" rpy="0 0 0" />
      <geometry>
        <box size="0.05 0.1 0.05"/>
      </geometry>
      <material name="Blue" />
    </visual>
  </link>

  <joint name="camera_joint" type="fixed">
    <parent link="base_floor"/>
    <child link="camera_link" />
    <origin xyz="0.3 0 0.2" rpy="0 0 0" />
  </joint>

  <gazebo reference="camera_link">
    <material>Gazebo/Blue</material>
    <turnGravityOff>false</turnGravityOff>
    <sensor type="camera" name="camera1">
      <update_rate>15.0</update_rate>
      <camera name="head">

          <pose>0 0 0 0 0 0</pose>

        <horizontal_fov>1.3962634</horizontal_fov>
        <image>
          <width>400</width>
          <height>400</height>
          <format>R8G8B8</format>
        </image>
        <clip>
          <near>0.01</near>
          <far>100</far>
        </clip>
        <noise>
          <type>gaussian</type>
          <stddev>0.007</stddev>
        </noise>
      </camera>
      <plugin name="camera_controller" filename="libgazebo_ros_camera.so">
        <alwaysOn>true</alwaysOn>
        <updateRate>0.0</updateRate>
        <cameraName>whill_simulator/camera1</cameraName>
        <imageTopicName>image_raw</imageTopicName>
        <cameraInfoTopicName>camera_info</cameraInfoTopicName>
        <frameName>camera_link</frameName>
        <hackBaseline>0.07</hackBaseline>
        <distortionK1>0.0</distortionK1>
        <distortionK2>0.0</distortionK2>
        <distortionK3>0.0</distortionK3>
        <distortionT1>0.0</distortionT1>
        <distortionT2>0.0</distortionT2>
      </plugin>
    </sensor>
  </gazebo>
    
    <!-- ===============  Transmission =============== -->

    <transmission name="right_wheel_trans">
        <type>transmission_interface/SimpleTransmission</type>
        <joint name="rightWheel">
            <hardwareInterface>hardware_interface/VelocityJointInterface</hardwareInterface>
        </joint>
        <actuator name="right_wheel_motor">
            <hardwareInterface>hardware_interface/VelocityJointInterface</hardwareInterface>
            <!-- <mechanicalReduction>30</mechanicalReduction> -->
            <mechanicalReduction>30</mechanicalReduction>
        </actuator>
    </transmission>

    <transmission name="left_wheel_trans">
        <type>transmission_interface/SimpleTransmission</type>
        <joint name="leftWheel">
            <hardwareInterface>hardware_interface/VelocityJointInterface</hardwareInterface>
        </joint>
        <actuator name="left_wheel_motor">
            <hardwareInterface>hardware_interface/VelocityJointInterface</hardwareInterface>
            <!-- <mechanicalReduction>30</mechanicalReduction> -->
            <mechanicalReduction>30</mechanicalReduction>
        </actuator>
    </transmission>

    <!-- ===============  Gazebo =============== -->
    <gazebo>
        <plugin name="gazebo_ros_control" filename="libgazebo_ros_control.so">
            <robotNamespace>/whill_simulator</robotNamespace>
            <legacyModeNS>true</legacyModeNS>
        </plugin>
    </gazebo>

    <gazebo reference="base_floor">
        <selfCollide>true</selfCollide>
        <mu1 value="0.05" />
        <mu2 value="0.05" />
    </gazebo>

    <gazebo reference="right_wheel_link">
        <selfCollide>true</selfCollide>
        <material>Gazebo/Gray</material>
        <mu1 value="0.8" />
        <mu2 value="0.8" />
    </gazebo>

    <gazebo reference="left_wheel_link">
        <selfCollide>true</selfCollide>
        <material>Gazebo/Gray</material>
        <mu1 value="0.8" />
        <mu2 value="0.8" />
    </gazebo>

    <gazebo reference="frontwheel_right">
        <selfCollide>true</selfCollide>
        <material>Gazebo/Gray</material>
        <mu1 value="0.0" />
        <mu2 value="0.0" />
    </gazebo>

    <gazebo reference="frontwheel_left">
        <selfCollide>true</selfCollide>
        <material>Gazebo/Gray</material>
        <mu1 value="0.0" />
        <mu2 value="0.0" />
    </gazebo>

</robot>

